<?xml version="1.0" encoding="UTF-8"?>
<robot xmlns:xacro="http://ros.org/wiki/xacro" name="cobotta">
  <xacro:include filename="$(find denso_descriptions)/common_description/common.xacro"/>

  <xacro:arg name="base_link_x" default="0"/>
  <xacro:arg name="base_link_y" default="0"/>
  <xacro:arg name="base_link_z" default="0"/>
  <xacro:arg name="base_link_yaw" default="0"/>
  <link name="world"/>
  <joint name="joint_w" type="fixed">
    <parent link="world"/>
    <child link="base_link"/>
    <origin rpy="0 0 $(arg base_link_yaw)" xyz="$(arg base_link_x) $(arg base_link_y) $(arg base_link_z)" />
  </joint>
  <link name="base_link">
    <visual>
      <origin rpy="0 0 0" xyz="0 0 0"/>
      <geometry>
        <mesh filename="package://denso_descriptions/cobotta_description/cobotta/meshes/base_link.dae" scale="1 1 1"/>
      </geometry>
    </visual>
    <collision>
      <origin rpy="0 0 0" xyz="0 0 0"/>
      <geometry>
        <mesh filename="package://denso_descriptions/cobotta_description/cobotta/meshes/base_link.dae" scale="1 1 1"/>
      </geometry>
    </collision>
    <xacro:inertia_macro radius="0.08" height="0.06" mass="1.4">
      <origin rpy="0.000000 0.000000 0.000000" xyz="-0.021310 0.000002 0.044011"/>
    </xacro:inertia_macro>
  </link>
  <link name="J1">
    <visual>
      <origin rpy="0 0 0" xyz="0 0 0"/>
      <geometry>
        <mesh filename="package://denso_descriptions/cobotta_description/cobotta/meshes/J1.dae" scale="1 1 1"/>
      </geometry>
    </visual>
    <collision>
      <origin rpy="0 0 0" xyz="0 0 0"/>
      <geometry>
        <mesh filename="package://denso_descriptions/cobotta_description/cobotta/meshes/J1.dae" scale="1 1 1"/>
      </geometry>
    </collision>
    <xacro:inertia_macro radius="0.06" height="0.1" mass="1.29">
      <origin rpy="0.000000 0.000000 0.000000" xyz="0.000000 0.000000 0.15" />
    </xacro:inertia_macro>
  </link>
  <joint name="joint_1" type="revolute">
    <parent link="base_link"/>
    <child link="J1"/>
    <origin rpy="0.000000 0.000000 0.000000" xyz="0.000000 0.000000 0.000000"/>
    <axis xyz="-0.000000 -0.000000 1.000000"/>
    <limit effort="1" lower="-2.617994" upper="2.617994" velocity="1"/>
    <dynamics damping="0" friction="0"/>
  </joint>
  <transmission name="trans_1">
    <type>transmission_interface/SimpleTransmission</type>
    <joint name="joint_1">
      <hardwareInterface>hardware_interface/PositionJointInterface</hardwareInterface>
    </joint>
    <actuator name="motor_1">
      <hardwareInterface>hardware_interface/PositionJointInterface</hardwareInterface>
      <mechanicalReduction>1</mechanicalReduction>
    </actuator>
  </transmission>
  <link name="J2">
  <visual>
    <origin rpy="0 0 0" xyz="0 0 0"/>
    <geometry>
      <mesh filename="package://denso_descriptions/cobotta_description/cobotta/meshes/J2.dae" scale="1 1 1"/>
    </geometry>
  </visual>
  <collision>
    <origin rpy="0 0 0" xyz="0 0 0"/>
    <geometry>
      <mesh filename="package://denso_descriptions/cobotta_description/cobotta/meshes/J2.dae" scale="1 1 1"/>
    </geometry>
  </collision>
  <xacro:inertia_macro radius="0.03" height="0.12" mass="0.39">
    <origin rpy="0.000000 0.000000 0.000000" xyz="-0.020000 0.100000 0.070000" />
  </xacro:inertia_macro>
  </link>
  <joint name="joint_2" type="revolute">
    <parent link="J1"/>
    <child link="J2"/>
    <origin rpy="0.000000 0.000000 0.000000" xyz="0.000000 0.000000 0.180000"/>
    <axis xyz="-0.000000 1.000000 -0.000000"/>
    <limit effort="1" lower="-1.047198" upper="1.745329" velocity="1"/>
    <dynamics damping="0" friction="0"/>
  </joint>
  <transmission name="trans_2">
    <type>transmission_interface/SimpleTransmission</type>
    <joint name="joint_2">
      <hardwareInterface>hardware_interface/PositionJointInterface</hardwareInterface>
    </joint>
    <actuator name="motor_2">
      <hardwareInterface>hardware_interface/PositionJointInterface</hardwareInterface>
      <mechanicalReduction>1</mechanicalReduction>
    </actuator>
  </transmission>
  <link name="J3">
    <visual>
      <origin rpy="0 0 0" xyz="0 0 0"/>
      <geometry>
        <mesh filename="package://denso_descriptions/cobotta_description/cobotta/meshes/J3.dae" scale="1 1 1"/>
      </geometry>
    </visual>
    <collision>
      <origin rpy="0 0 0" xyz="0 0 0"/>
      <geometry>
        <mesh filename="package://denso_descriptions/cobotta_description/cobotta/meshes/J3.dae" scale="1 1 1"/>
      </geometry>
    </collision>
    <xacro:inertia_macro radius="0.03" height="0.11" mass="0.35">
      <origin rpy="0.000000 0.000000 0.000000" xyz="-0.01000 0.020000 0.030000" />
    </xacro:inertia_macro>
  </link>
  <joint name="joint_3" type="revolute">
    <parent link="J2"/>
    <child link="J3"/>
    <origin rpy="0.000000 0.000000 0.000000" xyz="0.000000 0.000000 0.165000"/>
    <axis xyz="-0.000000 1.000000 -0.000000"/>
    <limit effort="1" lower="0.3141593" upper="2.443461" velocity="1"/>
    <dynamics damping="0" friction="0"/>
  </joint>
  <transmission name="trans_3">
    <type>transmission_interface/SimpleTransmission</type>
    <joint name="joint_3">
      <hardwareInterface>hardware_interface/PositionJointInterface</hardwareInterface>
    </joint>
    <actuator name="motor_3">
      <hardwareInterface>hardware_interface/PositionJointInterface</hardwareInterface>
      <mechanicalReduction>1</mechanicalReduction>
    </actuator>
  </transmission>
  <link name="J4">
    <visual>
      <origin rpy="0 0 0" xyz="0 0 0"/>
      <geometry>
        <mesh filename="package://denso_descriptions/cobotta_description/cobotta/meshes/J4.dae" scale="1 1 1"/>
      </geometry>
    </visual>
    <collision>
      <origin rpy="0 0 0" xyz="0 0 0"/>
      <geometry>
        <mesh filename="package://denso_descriptions/cobotta_description/cobotta/meshes/J4.dae" scale="1 1 1"/>
      </geometry>
    </collision>
    <xacro:inertia_macro radius="0.03" height="0.11" mass="0.35">
      <origin rpy="0.000000 0.000000 0.000000" xyz="0.0000 0.000000 0.055000"/>
    </xacro:inertia_macro>
  </link>
  <joint name="joint_4" type="revolute">
    <parent link="J3"/>
    <child link="J4"/>
    <origin rpy="0.000000 0.000000 0.000000" xyz="-0.012000 0.020000 0.088000"/>
    <axis xyz="-0.000000 -0.000000 1.000000"/>
    <limit effort="1" lower="-2.9" upper="2.9" velocity="1"/>
    <dynamics damping="0" friction="0"/>
  </joint>
  <transmission name="trans_4">
    <type>transmission_interface/SimpleTransmission</type>
    <joint name="joint_4">
      <hardwareInterface>hardware_interface/PositionJointInterface</hardwareInterface>
    </joint>
    <actuator name="motor_4">
      <hardwareInterface>hardware_interface/PositionJointInterface</hardwareInterface>
      <mechanicalReduction>1</mechanicalReduction>
    </actuator>
  </transmission>
  <link name="J5">
    <visual>
      <origin rpy="0 0 0" xyz="0 0 0"/>
      <geometry>
        <mesh filename="package://denso_descriptions/cobotta_description/cobotta/meshes/J5.dae" scale="1 1 1"/>
      </geometry>
    </visual>
    <collision>
      <origin rpy="0 0 0" xyz="0 0 0"/>
      <geometry>
        <mesh filename="package://denso_descriptions/cobotta_description/cobotta/meshes/J5.dae" scale="1 1 1"/>
      </geometry>
    </collision>
    <xacro:inertia_macro radius="0.03" height="0.06" mass="0.19">
      <origin rpy="0.000000 0.000000 0.000000" xyz="0.000000 -0.040000 0.015000"/>
    </xacro:inertia_macro>
  </link>
  <joint name="joint_5" type="revolute">
    <parent link="J4"/>
    <child link="J5"/>
    <origin rpy="0.000000 0.000000 0.000000" xyz="0.000000 -0.020000 0.089500"/>
    <axis xyz="-0.000000 1.000000 -0.000000"/>
    <limit effort="1" lower="-1.658063" upper="2.356194" velocity="1"/>
    <dynamics damping="0" friction="0"/>
  </joint>
  <transmission name="trans_5">
    <type>transmission_interface/SimpleTransmission</type>
    <joint name="joint_5">
      <hardwareInterface>hardware_interface/PositionJointInterface</hardwareInterface>
    </joint>
    <actuator name="motor_5">
      <hardwareInterface>hardware_interface/PositionJointInterface</hardwareInterface>
      <mechanicalReduction>1</mechanicalReduction>
    </actuator>
  </transmission>
  <link name="J6">
    <visual>
      <origin rpy="0 0 0" xyz="0 0 0"/>
      <geometry>
        <mesh filename="package://denso_descriptions/cobotta_description/cobotta/meshes/J6.dae" scale="1 1 1"/>
      </geometry>
    </visual>
    <collision>
      <origin rpy="0 0 0" xyz="0 0 0"/>
      <geometry>
        <mesh filename="package://denso_descriptions/cobotta_description/cobotta/meshes/J6.dae" scale="1 1 1"/>
      </geometry>
    </collision>
    <xacro:inertia_macro radius="0.03" height="0.01" mass="0.03">
      <origin rpy="0.000000 0.000000 0.000000" xyz="0.000000 0.000000 0.000000" />
    </xacro:inertia_macro>
  </link>
  <joint name="joint_6" type="revolute">
    <parent link="J5"/>
    <child link="J6"/>
    <origin rpy="0.000000 0.000000 0.000000" xyz="0.000000 -0.044500 0.042000"/>
    <axis xyz="-0.000000 -0.000000 1.000000"/>
    <limit effort="1" lower="-2.9" upper="2.9" velocity="1"/>
    <dynamics damping="0" friction="0"/>
  </joint>
  <transmission name="trans_6">
    <type>transmission_interface/SimpleTransmission</type>
    <joint name="joint_6">
      <hardwareInterface>hardware_interface/PositionJointInterface</hardwareInterface>
    </joint>
    <actuator name="motor_6">
      <hardwareInterface>hardware_interface/PositionJointInterface</hardwareInterface>
      <mechanicalReduction>1</mechanicalReduction>
    </actuator>
  </transmission>
</robot>
