<?xml version="1.0" ?>
<!-- =================================================================================== -->
<!-- |    This document was autogenerated by xacro from vs087_and_tercero.urdf.xacro   | -->
<!-- |    EDITING THIS FILE BY HAND IS NOT RECOMMENDED                                 | -->
<!-- =================================================================================== -->
<robot name="vs087" xmlns:xacro="http://ros.org/wiki/xacro">
  <gazebo>
    <plugin filename="libgazebo_ros_control.so" name="gazebo_ros_control">
      <robotNamespace>/vs087</robotNamespace>
    </plugin>
  </gazebo>
  <link name="world"/>
  <joint name="joint_w" type="fixed">
    <parent link="world"/>
    <child link="base_link"/>
  </joint>
  <link name="base_link">
    <visual>
      <origin rpy="0 0 0" xyz="0 0 0"/>
      <geometry>
        <mesh filename="package://denso_descriptions/vs087_description/vs087/meshes/base_link.dae" scale="1 1 1"/>
      </geometry>
    </visual>
    <collision>
      <origin rpy="0 0 0" xyz="0 0 0"/>
      <geometry>
        <mesh filename="package://denso_descriptions/vs087_description/vs087/meshes/base_link.dae" scale="1 1 1"/>
      </geometry>
    </collision>
    <inertial>
      <mass value="1"/>
      <origin rpy="0.000000 0.000000 0.000000" xyz="0.000000 0.000000 0.000000"/>
      <inertia ixx="1" ixy="0" ixz="0" iyy="1" iyz="0" izz="1"/>
    </inertial>
  </link>
  <link name="J1">
    <visual>
      <origin rpy="0 0 0" xyz="0 0 0"/>
      <geometry>
        <mesh filename="package://denso_descriptions/vs087_description/vs087/meshes/J1.dae" scale="1 1 1"/>
      </geometry>
    </visual>
    <collision>
      <origin rpy="0 0 0" xyz="0 0 0"/>
      <geometry>
        <mesh filename="package://denso_descriptions/vs087_description/vs087/meshes/J1.dae" scale="1 1 1"/>
      </geometry>
    </collision>
    <inertial>
      <mass value="1"/>
      <origin rpy="0.000000 0.000000 0.000000" xyz="0.000000 0.000000 0.000000"/>
      <inertia ixx="1" ixy="0" ixz="0" iyy="1" iyz="0" izz="1"/>
    </inertial>
  </link>
  <joint name="joint_1" type="revolute">
    <parent link="base_link"/>
    <child link="J1"/>
    <origin rpy="0.000000 0.000000 0.000000" xyz="0.000000 0.000000 0.197500"/>
    <axis xyz="-0.000000 -0.000000 1.000000"/>
    <limit effort="1" lower="-2.96426720159" upper="2.96444173451" velocity="3.14159265358979"/>
    <dynamics damping="0" friction="0"/>
  </joint>
  <transmission name="trans_1">
    <type>transmission_interface/SimpleTransmission</type>
    <joint name="joint_1">
      <hardwareInterface>hardware_interface/PositionJointInterface</hardwareInterface>
    </joint>
    <actuator name="motor_1">
      <hardwareInterface>hardware_interface/PositionJointInterface</hardwareInterface>
      <mechanicalReduction>1</mechanicalReduction>
    </actuator>
  </transmission>
  <link name="J2">
    <visual>
      <origin rpy="0 0 0" xyz="0 0 0"/>
      <geometry>
        <mesh filename="package://denso_descriptions/vs087_description/vs087/meshes/J2.dae" scale="1 1 1"/>
      </geometry>
    </visual>
    <collision>
      <origin rpy="0 0 0" xyz="0 0 0"/>
      <geometry>
        <mesh filename="package://denso_descriptions/vs087_description/vs087/meshes/J2.dae" scale="1 1 1"/>
      </geometry>
    </collision>
    <inertial>
      <mass value="1"/>
      <origin rpy="0.000000 0.000000 0.000000" xyz="0.000000 0.000000 0.000000"/>
      <inertia ixx="1" ixy="0" ixz="0" iyy="1" iyz="0" izz="1"/>
    </inertial>
  </link>
  <joint name="joint_2" type="revolute">
    <parent link="J1"/>
    <child link="J2"/>
    <origin rpy="0.000000 0.000000 0.000000" xyz="0.030000 0.000000 0.197500"/>
    <axis xyz="-0.000000 1.000000 -0.000000"/>
    <limit effort="1" lower="-1.7453117987" upper="2.35601995727" velocity="2.87979326579064"/>
    <dynamics damping="0" friction="0"/>
  </joint>
  <transmission name="trans_2">
    <type>transmission_interface/SimpleTransmission</type>
    <joint name="joint_2">
      <hardwareInterface>hardware_interface/PositionJointInterface</hardwareInterface>
    </joint>
    <actuator name="motor_2">
      <hardwareInterface>hardware_interface/PositionJointInterface</hardwareInterface>
      <mechanicalReduction>1</mechanicalReduction>
    </actuator>
  </transmission>
  <link name="J3">
    <visual>
      <origin rpy="0 0 0" xyz="0 0 0"/>
      <geometry>
        <mesh filename="package://denso_descriptions/vs087_description/vs087/meshes/J3.dae" scale="1 1 1"/>
      </geometry>
    </visual>
    <collision>
      <origin rpy="0 0 0" xyz="0 0 0"/>
      <geometry>
        <mesh filename="package://denso_descriptions/vs087_description/vs087/meshes/J3.dae" scale="1 1 1"/>
      </geometry>
    </collision>
    <inertial>
      <mass value="1"/>
      <origin rpy="0.000000 0.000000 0.000000" xyz="0.000000 0.000000 0.000000"/>
      <inertia ixx="1" ixy="0" ixz="0" iyy="1" iyz="0" izz="1"/>
    </inertial>
  </link>
  <joint name="joint_3" type="revolute">
    <parent link="J2"/>
    <child link="J3"/>
    <origin rpy="0.000000 0.000000 0.000000" xyz="0.000000 0.000000 0.445000"/>
    <axis xyz="-0.000000 1.000000 -0.000000"/>
    <!-- <limit effort="1" lower="-1.1836822987" upper="2.54469004941" velocity="3.45575191894877" /> -->
    <limit effort="1" lower="-1.1836822987" upper="2.56" velocity="3.45575191894877"/>
    <dynamics damping="0" friction="0"/>
  </joint>
  <transmission name="trans_3">
    <type>transmission_interface/SimpleTransmission</type>
    <joint name="joint_3">
      <hardwareInterface>hardware_interface/PositionJointInterface</hardwareInterface>
    </joint>
    <actuator name="motor_3">
      <hardwareInterface>hardware_interface/PositionJointInterface</hardwareInterface>
      <mechanicalReduction>1</mechanicalReduction>
    </actuator>
  </transmission>
  <link name="J4">
    <visual>
      <origin rpy="0 0 0" xyz="0 0 0"/>
      <geometry>
        <mesh filename="package://denso_descriptions/vs087_description/vs087/meshes/J4.dae" scale="1 1 1"/>
      </geometry>
    </visual>
    <collision>
      <origin rpy="0 0 0" xyz="0 0 0"/>
      <geometry>
        <mesh filename="package://denso_descriptions/vs087_description/vs087/meshes/J4.dae" scale="1 1 1"/>
      </geometry>
    </collision>
    <inertial>
      <mass value="1"/>
      <origin rpy="0.000000 0.000000 0.000000" xyz="0.000000 0.000000 0.000000"/>
      <inertia ixx="1" ixy="0" ixz="0" iyy="1" iyz="0" izz="1"/>
    </inertial>
  </link>
  <joint name="joint_4" type="revolute">
    <parent link="J3"/>
    <child link="J4"/>
    <origin rpy="0.000000 0.000000 0.000000" xyz="-0.020000 0.000000 0.287000"/>
    <axis xyz="-0.000000 -0.000000 1.000000"/>
    <limit effort="1" lower="-3.14421064747" upper="3.13042254638" velocity="4.31968989868597"/>
    <dynamics damping="0" friction="0"/>
  </joint>
  <transmission name="trans_4">
    <type>transmission_interface/SimpleTransmission</type>
    <joint name="joint_4">
      <hardwareInterface>hardware_interface/PositionJointInterface</hardwareInterface>
    </joint>
    <actuator name="motor_4">
      <hardwareInterface>hardware_interface/PositionJointInterface</hardwareInterface>
      <mechanicalReduction>1</mechanicalReduction>
    </actuator>
  </transmission>
  <link name="J5">
    <visual>
      <origin rpy="0 0 0" xyz="0 0 0"/>
      <geometry>
        <mesh filename="package://denso_descriptions/vs087_description/vs087/meshes/J5.dae" scale="1 1 1"/>
      </geometry>
    </visual>
    <collision>
      <origin rpy="0 0 0" xyz="0 0 0"/>
      <geometry>
        <mesh filename="package://denso_descriptions/vs087_description/vs087/meshes/J5.dae" scale="1 1 1"/>
      </geometry>
    </collision>
    <inertial>
      <mass value="1"/>
      <origin rpy="0.000000 0.000000 0.000000" xyz="0.000000 0.000000 0.000000"/>
      <inertia ixx="1" ixy="0" ixz="0" iyy="1" iyz="0" izz="1"/>
    </inertial>
  </link>
  <joint name="joint_5" type="revolute">
    <parent link="J4"/>
    <child link="J5"/>
    <origin rpy="0.000000 0.000000 0.000000" xyz="0.000000 0.000000 0.143000"/>
    <axis xyz="-0.000000 1.000000 -0.000000"/>
    <limit effort="1" lower="-0.165806278939" upper="1.73677713866" velocity="4.31968989868597"/>
    <dynamics damping="0" friction="0"/>
  </joint>
  <transmission name="trans_5">
    <type>transmission_interface/SimpleTransmission</type>
    <joint name="joint_5">
      <hardwareInterface>hardware_interface/PositionJointInterface</hardwareInterface>
    </joint>
    <actuator name="motor_5">
      <hardwareInterface>hardware_interface/PositionJointInterface</hardwareInterface>
      <mechanicalReduction>1</mechanicalReduction>
    </actuator>
  </transmission>
  <link name="J6">
    <visual>
      <origin rpy="0 0 0" xyz="0 0 0"/>
      <geometry>
        <mesh filename="package://denso_descriptions/vs087_description/vs087/meshes/J6.dae" scale="1 1 1"/>
      </geometry>
    </visual>
    <collision>
      <origin rpy="0 0 0" xyz="0 0 0"/>
      <geometry>
        <mesh filename="package://denso_descriptions/vs087_description/vs087/meshes/J6.dae" scale="1 1 1"/>
      </geometry>
    </collision>
    <inertial>
      <mass value="1"/>
      <origin rpy="0.000000 0.000000 0.000000" xyz="0.000000 0.000000 0.000000"/>
      <inertia ixx="1" ixy="0" ixz="0" iyy="1" iyz="0" izz="1"/>
    </inertial>
  </link>
  <joint name="joint_6" type="revolute">
    <parent link="J5"/>
    <child link="J6"/>
    <origin rpy="0.000000 0.000000 0.000000" xyz="0.000000 0.000000 0.080000"/>
    <axis xyz="-0.000000 -0.000000 1.000000"/>
    <!-- <limit effort="1" lower="2.13750473492" upper="6.283185" velocity="6.91150383789755" /> -->
    <limit effort="1" lower="0.0" upper="6.283185" velocity="6.91150383789755"/>
    <dynamics damping="0" friction="0"/>
  </joint>
  <transmission name="trans_6">
    <type>transmission_interface/SimpleTransmission</type>
    <joint name="joint_6">
      <hardwareInterface>hardware_interface/PositionJointInterface</hardwareInterface>
    </joint>
    <actuator name="motor_6">
      <hardwareInterface>hardware_interface/PositionJointInterface</hardwareInterface>
      <mechanicalReduction>1</mechanicalReduction>
    </actuator>
  </transmission>
  <!-- <xacro:include filename="$(find tercero_description)/urdf/common.xacro"/> -->
  <!-- =============== Link & Joint =============== -->
  <!-- hand_body -->
  <link name="hand_link"/>
  <joint name="hand_link_joint" type="fixed">
    <origin rpy="3.14 0 0" xyz="0 0 0"/>
    <parent link="hand_link"/>
    <child link="hand_body_link"/>
  </joint>
  <link name="hand_body_link">
    <visual>
      <geometry>
        <mesh filename="package://tercero_description/meshes/DAE/hand_body.dae"/>
      </geometry>
    </visual>
    <collision>
      <geometry>
        <mesh filename="package://tercero_description/meshes/STL/easy_hand_body.stl"/>
      </geometry>
    </collision>
    <inertial>
      <origin xyz="0 0 0"/>
      <mass value="1.173"/>
      <inertia ixx="0.008" ixy="0.0" ixz="0.0" iyy="0.008" iyz="0.0" izz="0.003"/>
    </inertial>
  </link>
  <joint name="finger_R_joint" type="prismatic">
    <origin rpy="0 0 0" xyz="0 0 0"/>
    <parent link="hand_body_link"/>
    <child link="finger_R"/>
    <axis xyz="0 -1 0"/>
    <limit effort="0.5293" lower="0" upper="0.06" velocity="6.159937255"/>
  </joint>
  <link name="finger_R">
    <visual>
      <geometry>
        <mesh filename="package://tercero_description/meshes/DAE/finger.dae"/>
      </geometry>
    </visual>
    <collision>
      <geometry>
        <mesh filename="package://tercero_description/meshes/STL/easy_finger.stl"/>
      </geometry>
    </collision>
    <inertial>
      <origin xyz="0 0 0"/>
      <mass value="0.145"/>
      <inertia ixx="0.002" ixy="0.0" ixz="0.0" iyy="0.002" iyz="0.0" izz="0.0"/>
    </inertial>
  </link>
  <transmission name="finger_R_transmission">
    <type>transmission_interface/SimpleTransmission</type>
    <joint name="finger_R_joint">
      <hardwareInterface>hardware_interface/PositionJointInterface</hardwareInterface>
    </joint>
    <actuator name="hand_motor1">
      <hardwareInterface>hardware_interface/PositionJointInterface</hardwareInterface>
      <mechanicalReduction>30</mechanicalReduction>
    </actuator>
  </transmission>
  <joint name="finger_L_joint" type="prismatic">
    <origin rpy="0 0 3.14" xyz="0 0 0"/>
    <parent link="hand_body_link"/>
    <child link="finger_L"/>
    <axis xyz="0 -1 0"/>
    <limit effort="0.5293" lower="0" upper="0.06" velocity="6.159937255"/>
  </joint>
  <link name="finger_L">
    <visual>
      <geometry>
        <mesh filename="package://tercero_description/meshes/DAE/finger.dae"/>
      </geometry>
    </visual>
    <collision>
      <geometry>
        <mesh filename="package://tercero_description/meshes/STL/easy_finger.stl"/>
      </geometry>
    </collision>
    <inertial>
      <origin xyz="0 0 0"/>
      <mass value="0.145"/>
      <inertia ixx="0.002" ixy="0.0" ixz="0.0" iyy="0.002" iyz="0.0" izz="0.0"/>
    </inertial>
  </link>
  <transmission name="finger_L_transmission">
    <type>transmission_interface/SimpleTransmission</type>
    <joint name="finger_L_joint">
      <hardwareInterface>hardware_interface/PositionJointInterface</hardwareInterface>
    </joint>
    <actuator name="hand_motor1">
      <hardwareInterface>hardware_interface/PositionJointInterface</hardwareInterface>
      <mechanicalReduction>30</mechanicalReduction>
    </actuator>
  </transmission>
  <joint name="finger_3rd_joint" type="prismatic">
    <origin rpy="0 0 0" xyz="0 0 0"/>
    <parent link="hand_body_link"/>
    <child link="finger_3rd"/>
    <axis xyz="0 0 -1"/>
    <limit effort="0.5293" lower="0" upper="0.035" velocity="6.159937255"/>
  </joint>
  <link name="finger_3rd">
    <visual>
      <geometry>
        <mesh filename="package://tercero_description/meshes/DAE/third_finger.dae"/>
      </geometry>
    </visual>
    <collision>
      <geometry>
        <mesh filename="package://tercero_description/meshes/STL/third_finger.stl"/>
      </geometry>
    </collision>
    <inertial>
      <origin xyz="0 0 0"/>
      <mass value="0.028"/>
      <inertia ixx="0.0" ixy="0.0" ixz="0.0" iyy="0.0" iyz="0.0" izz="0.0"/>
    </inertial>
  </link>
  <transmission name="finger_3rd_transmission">
    <type>transmission_interface/SimpleTransmission</type>
    <joint name="finger_3rd_joint">
      <hardwareInterface>hardware_interface/PositionJointInterface</hardwareInterface>
    </joint>
    <actuator name="hand_motor1">
      <hardwareInterface>hardware_interface/PositionJointInterface</hardwareInterface>
      <mechanicalReduction>30</mechanicalReduction>
    </actuator>
  </transmission>
  <joint name="gripper_joint" type="fixed">
    <origin rpy="0 0 0" xyz="0 0 0"/>
    <parent link="J6"/>
    <child link="hand_link"/>
  </joint>
</robot>
