<?xml version="1.0" ?>
<!-- =================================================================================== -->
<!-- |    This document was autogenerated by xacro from vs087_and_mhand2.urdf.xacro    | -->
<!-- |    EDITING THIS FILE BY HAND IS NOT RECOMMENDED                                 | -->
<!-- =================================================================================== -->
<robot name="vs087" xmlns:xacro="http://ros.org/wiki/xacro">
  <gazebo>
    <plugin filename="libgazebo_ros_control.so" name="gazebo_ros_control">
      <robotNamespace>/vs087</robotNamespace>
    </plugin>
  </gazebo>
  <link name="world"/>
  <joint name="joint_w" type="fixed">
    <parent link="world"/>
    <child link="base_link"/>
  </joint>
  <link name="base_link">
    <visual>
      <origin rpy="0 0 0" xyz="0 0 0"/>
      <geometry>
        <mesh filename="package://denso_descriptions/vs087_description/vs087/meshes/base_link.dae" scale="1 1 1"/>
      </geometry>
    </visual>
    <collision>
      <origin rpy="0 0 0" xyz="0 0 0"/>
      <geometry>
        <mesh filename="package://denso_descriptions/vs087_description/vs087/meshes/base_link.dae" scale="1 1 1"/>
      </geometry>
    </collision>
    <inertial>
      <mass value="1"/>
      <origin rpy="0.000000 0.000000 0.000000" xyz="0.000000 0.000000 0.000000"/>
      <inertia ixx="1" ixy="0" ixz="0" iyy="1" iyz="0" izz="1"/>
    </inertial>
  </link>
  <link name="J1">
    <visual>
      <origin rpy="0 0 0" xyz="0 0 0"/>
      <geometry>
        <mesh filename="package://denso_descriptions/vs087_description/vs087/meshes/J1.dae" scale="1 1 1"/>
      </geometry>
    </visual>
    <collision>
      <origin rpy="0 0 0" xyz="0 0 0"/>
      <geometry>
        <mesh filename="package://denso_descriptions/vs087_description/vs087/meshes/J1.dae" scale="1 1 1"/>
      </geometry>
    </collision>
    <inertial>
      <mass value="1"/>
      <origin rpy="0.000000 0.000000 0.000000" xyz="0.000000 0.000000 0.000000"/>
      <inertia ixx="1" ixy="0" ixz="0" iyy="1" iyz="0" izz="1"/>
    </inertial>
  </link>
  <joint name="joint_1" type="revolute">
    <parent link="base_link"/>
    <child link="J1"/>
    <origin rpy="0.000000 0.000000 0.000000" xyz="0.000000 0.000000 0.197500"/>
    <axis xyz="-0.000000 -0.000000 1.000000"/>
    <limit effort="1" lower="-2.96426720159" upper="2.96444173451" velocity="3.14159265358979"/>
    <dynamics damping="0" friction="0"/>
  </joint>
  <transmission name="trans_1">
    <type>transmission_interface/SimpleTransmission</type>
    <joint name="joint_1">
      <hardwareInterface>hardware_interface/PositionJointInterface</hardwareInterface>
    </joint>
    <actuator name="motor_1">
      <hardwareInterface>hardware_interface/PositionJointInterface</hardwareInterface>
      <mechanicalReduction>1</mechanicalReduction>
    </actuator>
  </transmission>
  <link name="J2">
    <visual>
      <origin rpy="0 0 0" xyz="0 0 0"/>
      <geometry>
        <mesh filename="package://denso_descriptions/vs087_description/vs087/meshes/J2.dae" scale="1 1 1"/>
      </geometry>
    </visual>
    <collision>
      <origin rpy="0 0 0" xyz="0 0 0"/>
      <geometry>
        <mesh filename="package://denso_descriptions/vs087_description/vs087/meshes/J2.dae" scale="1 1 1"/>
      </geometry>
    </collision>
    <inertial>
      <mass value="1"/>
      <origin rpy="0.000000 0.000000 0.000000" xyz="0.000000 0.000000 0.000000"/>
      <inertia ixx="1" ixy="0" ixz="0" iyy="1" iyz="0" izz="1"/>
    </inertial>
  </link>
  <joint name="joint_2" type="revolute">
    <parent link="J1"/>
    <child link="J2"/>
    <origin rpy="0.000000 0.000000 0.000000" xyz="0.030000 0.000000 0.197500"/>
    <axis xyz="-0.000000 1.000000 -0.000000"/>
    <limit effort="1" lower="-1.7453117987" upper="2.35601995727" velocity="2.87979326579064"/>
    <dynamics damping="0" friction="0"/>
  </joint>
  <transmission name="trans_2">
    <type>transmission_interface/SimpleTransmission</type>
    <joint name="joint_2">
      <hardwareInterface>hardware_interface/PositionJointInterface</hardwareInterface>
    </joint>
    <actuator name="motor_2">
      <hardwareInterface>hardware_interface/PositionJointInterface</hardwareInterface>
      <mechanicalReduction>1</mechanicalReduction>
    </actuator>
  </transmission>
  <link name="J3">
    <visual>
      <origin rpy="0 0 0" xyz="0 0 0"/>
      <geometry>
        <mesh filename="package://denso_descriptions/vs087_description/vs087/meshes/J3.dae" scale="1 1 1"/>
      </geometry>
    </visual>
    <collision>
      <origin rpy="0 0 0" xyz="0 0 0"/>
      <geometry>
        <mesh filename="package://denso_descriptions/vs087_description/vs087/meshes/J3.dae" scale="1 1 1"/>
      </geometry>
    </collision>
    <inertial>
      <mass value="1"/>
      <origin rpy="0.000000 0.000000 0.000000" xyz="0.000000 0.000000 0.000000"/>
      <inertia ixx="1" ixy="0" ixz="0" iyy="1" iyz="0" izz="1"/>
    </inertial>
  </link>
  <joint name="joint_3" type="revolute">
    <parent link="J2"/>
    <child link="J3"/>
    <origin rpy="0.000000 0.000000 0.000000" xyz="0.000000 0.000000 0.445000"/>
    <axis xyz="-0.000000 1.000000 -0.000000"/>
    <!-- <limit effort="1" lower="-1.1836822987" upper="2.54469004941" velocity="3.45575191894877" /> -->
    <limit effort="1" lower="-1.1836822987" upper="2.56" velocity="3.45575191894877"/>
    <dynamics damping="0" friction="0"/>
  </joint>
  <transmission name="trans_3">
    <type>transmission_interface/SimpleTransmission</type>
    <joint name="joint_3">
      <hardwareInterface>hardware_interface/PositionJointInterface</hardwareInterface>
    </joint>
    <actuator name="motor_3">
      <hardwareInterface>hardware_interface/PositionJointInterface</hardwareInterface>
      <mechanicalReduction>1</mechanicalReduction>
    </actuator>
  </transmission>
  <link name="J4">
    <visual>
      <origin rpy="0 0 0" xyz="0 0 0"/>
      <geometry>
        <mesh filename="package://denso_descriptions/vs087_description/vs087/meshes/J4.dae" scale="1 1 1"/>
      </geometry>
    </visual>
    <collision>
      <origin rpy="0 0 0" xyz="0 0 0"/>
      <geometry>
        <mesh filename="package://denso_descriptions/vs087_description/vs087/meshes/J4.dae" scale="1 1 1"/>
      </geometry>
    </collision>
    <inertial>
      <mass value="1"/>
      <origin rpy="0.000000 0.000000 0.000000" xyz="0.000000 0.000000 0.000000"/>
      <inertia ixx="1" ixy="0" ixz="0" iyy="1" iyz="0" izz="1"/>
    </inertial>
  </link>
  <joint name="joint_4" type="revolute">
    <parent link="J3"/>
    <child link="J4"/>
    <origin rpy="0.000000 0.000000 0.000000" xyz="-0.020000 0.000000 0.287000"/>
    <axis xyz="-0.000000 -0.000000 1.000000"/>
    <limit effort="1" lower="-3.14421064747" upper="3.13042254638" velocity="4.31968989868597"/>
    <dynamics damping="0" friction="0"/>
  </joint>
  <transmission name="trans_4">
    <type>transmission_interface/SimpleTransmission</type>
    <joint name="joint_4">
      <hardwareInterface>hardware_interface/PositionJointInterface</hardwareInterface>
    </joint>
    <actuator name="motor_4">
      <hardwareInterface>hardware_interface/PositionJointInterface</hardwareInterface>
      <mechanicalReduction>1</mechanicalReduction>
    </actuator>
  </transmission>
  <link name="J5">
    <visual>
      <origin rpy="0 0 0" xyz="0 0 0"/>
      <geometry>
        <mesh filename="package://denso_descriptions/vs087_description/vs087/meshes/J5.dae" scale="1 1 1"/>
      </geometry>
    </visual>
    <collision>
      <origin rpy="0 0 0" xyz="0 0 0"/>
      <geometry>
        <mesh filename="package://denso_descriptions/vs087_description/vs087/meshes/J5.dae" scale="1 1 1"/>
      </geometry>
    </collision>
    <inertial>
      <mass value="1"/>
      <origin rpy="0.000000 0.000000 0.000000" xyz="0.000000 0.000000 0.000000"/>
      <inertia ixx="1" ixy="0" ixz="0" iyy="1" iyz="0" izz="1"/>
    </inertial>
  </link>
  <joint name="joint_5" type="revolute">
    <parent link="J4"/>
    <child link="J5"/>
    <origin rpy="0.000000 0.000000 0.000000" xyz="0.000000 0.000000 0.143000"/>
    <axis xyz="-0.000000 1.000000 -0.000000"/>
    <limit effort="1" lower="-0.165806278939" upper="1.73677713866" velocity="4.31968989868597"/>
    <dynamics damping="0" friction="0"/>
  </joint>
  <transmission name="trans_5">
    <type>transmission_interface/SimpleTransmission</type>
    <joint name="joint_5">
      <hardwareInterface>hardware_interface/PositionJointInterface</hardwareInterface>
    </joint>
    <actuator name="motor_5">
      <hardwareInterface>hardware_interface/PositionJointInterface</hardwareInterface>
      <mechanicalReduction>1</mechanicalReduction>
    </actuator>
  </transmission>
  <link name="J6">
    <visual>
      <origin rpy="0 0 0" xyz="0 0 0"/>
      <geometry>
        <mesh filename="package://denso_descriptions/vs087_description/vs087/meshes/J6.dae" scale="1 1 1"/>
      </geometry>
    </visual>
    <collision>
      <origin rpy="0 0 0" xyz="0 0 0"/>
      <geometry>
        <mesh filename="package://denso_descriptions/vs087_description/vs087/meshes/J6.dae" scale="1 1 1"/>
      </geometry>
    </collision>
    <inertial>
      <mass value="1"/>
      <origin rpy="0.000000 0.000000 0.000000" xyz="0.000000 0.000000 0.000000"/>
      <inertia ixx="1" ixy="0" ixz="0" iyy="1" iyz="0" izz="1"/>
    </inertial>
  </link>
  <joint name="joint_6" type="revolute">
    <parent link="J5"/>
    <child link="J6"/>
    <origin rpy="0.000000 0.000000 0.000000" xyz="0.000000 0.000000 0.080000"/>
    <axis xyz="-0.000000 -0.000000 1.000000"/>
    <!-- <limit effort="1" lower="2.13750473492" upper="6.283185" velocity="6.91150383789755" /> -->
    <limit effort="1" lower="0.0" upper="6.283185" velocity="6.91150383789755"/>
    <dynamics damping="0" friction="0"/>
  </joint>
  <transmission name="trans_6">
    <type>transmission_interface/SimpleTransmission</type>
    <joint name="joint_6">
      <hardwareInterface>hardware_interface/PositionJointInterface</hardwareInterface>
    </joint>
    <actuator name="motor_6">
      <hardwareInterface>hardware_interface/PositionJointInterface</hardwareInterface>
      <mechanicalReduction>1</mechanicalReduction>
    </actuator>
  </transmission>
  <!-- =============== Link & Joint =============== -->
  <!-- mhand_body -->
  <link name="hand_link"/>
  <joint name="mhand_link_joint" type="fixed">
    <origin xyz="0 0 0"/>
    <parent link="hand_link"/>
    <child link="mhand_body_link"/>
  </joint>
  <link name="mhand_body_link">
    <visual>
      <geometry>
        <mesh filename="package://mhand_description/meshes/DAE/mhand2_body_origin.dae"/>
      </geometry>
      <!-- <material> -->
      <!--   <color rgba="0.8 0 0.8 2.0"/> -->
      <!-- </material> -->
    </visual>
    <collision>
      <geometry>
        <mesh filename="package://mhand_description/meshes/STL/mhand2_body.stl"/>
      </geometry>
    </collision>
    <inertial>
      <origin xyz="0 0 0"/>
      <mass value="0.968"/>
      <inertia ixx="0.002" ixy="0.0" ixz="0.0" iyy="0.003" iyz="0.0" izz="0.001"/>
    </inertial>
  </link>
  <joint name="finger_A_joint" type="revolute">
    <origin rpy="3.14 -1.57 2.09" xyz="-0.011 0.019 0.135"/>
    <parent link="mhand_body_link"/>
    <child link="mhand_finger_A"/>
    <axis xyz="0 1 0"/>
    <limit effort="0.5293" lower="-1.22" upper="0" velocity="6.159937255"/>
  </joint>
  <link name="mhand_finger_A">
    <visual>
      <geometry>
        <mesh filename="package://mhand_description/meshes/DAE/mhand_finger.dae"/>
      </geometry>
    </visual>
    <collision>
      <geometry>
        <mesh filename="package://mhand_description/meshes/STL/mhand_finger.stl"/>
      </geometry>
    </collision>
    <inertial>
      <origin xyz="0 0 0"/>
      <mass value="0.968"/>
      <inertia ixx="0.002" ixy="0.0" ixz="0.0" iyy="0.003" iyz="0.0" izz="0.001"/>
    </inertial>
  </link>
  <transmission name="finger_trans_A">
    <type>transmission_interface/SimpleTransmission</type>
    <joint name="finger_A_joint">
      <hardwareInterface>hardware_interface/PositionJointInterface</hardwareInterface>
    </joint>
    <actuator name="mhand_motor">
      <hardwareInterface>hardware_interface/PositionJointInterface</hardwareInterface>
      <mechanicalReduction>30</mechanicalReduction>
    </actuator>
  </transmission>
  <joint name="finger_B_joint" type="revolute">
    <origin rpy="3.14 -1.57 -1.05" xyz="-0.007 -0.029 0.135"/>
    <parent link="mhand_body_link"/>
    <child link="mhand_finger_B"/>
    <axis xyz="0 1 0"/>
    <limit effort="0.5293" lower="-1.22" upper="0" velocity="6.159937255"/>
  </joint>
  <link name="mhand_finger_B">
    <visual>
      <geometry>
        <mesh filename="package://mhand_description/meshes/DAE/mhand_finger.dae"/>
      </geometry>
    </visual>
    <collision>
      <geometry>
        <mesh filename="package://mhand_description/meshes/STL/mhand_finger.stl"/>
      </geometry>
    </collision>
    <inertial>
      <origin xyz="0 0 0"/>
      <mass value="0.968"/>
      <inertia ixx="0.002" ixy="0.0" ixz="0.0" iyy="0.003" iyz="0.0" izz="0.001"/>
    </inertial>
  </link>
  <transmission name="finger_trans_B">
    <type>transmission_interface/SimpleTransmission</type>
    <joint name="finger_B_joint">
      <hardwareInterface>hardware_interface/PositionJointInterface</hardwareInterface>
    </joint>
    <actuator name="mhand_motor">
      <hardwareInterface>hardware_interface/PositionJointInterface</hardwareInterface>
      <mechanicalReduction>30</mechanicalReduction>
    </actuator>
  </transmission>
  <joint name="finger_C_joint" type="revolute">
    <origin rpy="3.14 -1.57 -1.05" xyz="0.028 -0.009 0.135"/>
    <parent link="mhand_body_link"/>
    <child link="mhand_finger_C"/>
    <axis xyz="0 1 0"/>
    <limit effort="0.5293" lower="-1.22" upper="0" velocity="6.159937255"/>
  </joint>
  <link name="mhand_finger_C">
    <visual>
      <geometry>
        <mesh filename="package://mhand_description/meshes/DAE/mhand_finger.dae"/>
      </geometry>
    </visual>
    <collision>
      <geometry>
        <mesh filename="package://mhand_description/meshes/STL/mhand_finger.stl"/>
      </geometry>
    </collision>
    <inertial>
      <origin xyz="0 0 0"/>
      <mass value="0.968"/>
      <inertia ixx="0.002" ixy="0.0" ixz="0.0" iyy="0.003" iyz="0.0" izz="0.001"/>
    </inertial>
  </link>
  <transmission name="finger_trans_C">
    <type>transmission_interface/SimpleTransmission</type>
    <joint name="finger_C_joint">
      <hardwareInterface>hardware_interface/PositionJointInterface</hardwareInterface>
    </joint>
    <actuator name="mhand_motor">
      <hardwareInterface>hardware_interface/PositionJointInterface</hardwareInterface>
      <mechanicalReduction>30</mechanicalReduction>
    </actuator>
  </transmission>
  <joint name="gripper_joint" type="fixed">
    <origin rpy="0 0 0" xyz="0 0 0"/>
    <parent link="J6"/>
    <child link="hand_link"/>
  </joint>
</robot>
